<?xml version="1.0"?>
<robot name="shuttle">


  <link name="base_link"/>

  <link name="body">
    <visual>
      <origin xyz="0.1 0 0.13" rpy="0 0 0"/>

      <geometry>
        <box size="0.4 0.2 0.05" />
        <!--mesh filename="file://$(arg models_directory)/shuttle_parts/navette_body.stl" scale="0.04 0.04 0.04"/-->
      </geometry>
    </visual>
    <collision>

      <origin xyz="0.1 0 0.13" rpy="0 0 0"/>

      <geometry>
        <box size="0.4 0.2 0.05" />
      </geometry>
      
      
      <surface>
        <friction>
          <ode>
            <mu>0.01</mu>
            <mu2>0.01</mu2>
          </ode>
        </friction>
        <bounce>
          <restitution_coefficient>0.01</restitution_coefficient>
          <threshold>0.01</threshold>
        </bounce>
        <contact>
          <ode>
            <max_vel>0.1</max_vel>
            <soft_cfm>0.8</soft_cfm>
            <soft_erp>0.2</soft_erp>
            <kd>2500</kd>
            <kp>10</kp>
            <min_depth>0.001</min_depth>
          </ode>
        </contact>
      </surface>
      
    </collision>

    <inertial>
      <origin xyz="0.15 0 0.12" rpy="0 0 0"/>
      <mass value="4.000000000" />
      <inertia ixx="0.014166667" ixy="0.000000000" ixz="0.000000000" iyy="0.054166667" iyz="0.000000000" izz="0.066666667"/>
    </inertial>
      
  </link>





  <link name="ski">
    <visual>
      <geometry>
        <box size="0.06 0.1 0.01" />
        <!--mesh filename="file://$(arg models_directory)/shuttle_parts/navette_body.stl" scale="0.04 0.04 0.04"/-->
      </geometry>
    </visual>
    <collision>
      <geometry>
        <box size="0.06 0.1 0.01" />
      </geometry>
      
      <surface>
        <friction>
          <ode>
            <mu>0.01</mu>
            <mu2>0.01</mu2>
          </ode>
        </friction>
      </surface>
    </collision>

    <inertial>
      <origin rpy="0 0 0" xyz="0 0 0" />
      <mass value="0.200000000" />
      <inertia ixx="0.000168333" ixy="0.000000000" ixz="0.000000000" iyy="0.000061667" iyz="0.000000000" izz="0.000226667"/>
    </inertial>
          
  </link>






  <link name="tail_plate">
    <visual>
      <geometry>
        <box size="0.03 0.1 0.01" />
      </geometry>
    </visual>

    <collision>
      <geometry>
        <box size="0.03 0.05 0.01" />
      </geometry>
    </collision>

    <inertial>
      <origin rpy="0 0 0" xyz="0 0 0" />
      <mass value="0.300000000" />
      <inertia ixx="0.000065000" ixy="0.000000000" ixz="0.000000000" iyy="0.000025000" iyz="0.000000000" izz="0.000085000"/>
    </inertial>
  </link>





  <link name="cylinder1">
    <visual>
      <geometry>
        <cylinder radius="0.055" length="0.04"/>
      </geometry>
    </visual>

    <collision>
      <geometry>
        <cylinder radius="0.055" length="0.04"/>
      </geometry>
      <surface>
        <friction>
          <ode>
            <mu>0.9</mu>
            <mu2>0.9</mu2>
          </ode>
        </friction>
      </surface>
    </collision>

    <inertial>
      <origin rpy="0 0 0" xyz="0 0 0" />
      <mass value="1.000000000" />
      <inertia ixx="0.001033333" ixy="0.000000000" ixz="0.000000000" iyy="0.001033333" iyz="0.000000000" izz="0.001250000"/>
    </inertial>
        </link>


  <link name="cylinder2">

    <visual>
      <geometry>
        <cylinder radius="0.055" length="0.04"/>
      </geometry>
    </visual>


    <collision>
      <geometry>
        <cylinder radius="0.055" length="0.04"/>
      </geometry>
    </collision>
    <inertial>
      <origin rpy="0 0 0" xyz="0 0 0" />
      <mass value="1.000000000" />
      <inertia ixx="0.001033333" ixy="0.000000000" ixz="0.000000000" iyy="0.001033333" iyz="0.000000000" izz="0.001250000"/>
    </inertial>
        </link>

  <link name="head_plate">
    <visual>
      <geometry>
        <box size="0.03 0.05 0.01" />
      </geometry>
    </visual>

    <collision>
      <geometry>
        <box size="0.03 0.05 0.01" />
      </geometry>
      <surface>
        <friction>
          <ode>
            <mu>0.01</mu>
            <mu2>0.01</mu2>
          </ode>
        </friction>
      </surface>

    </collision>

    <inertial>
      <origin rpy="0 0 0" xyz="0 0 0" />
      <mass value="0.300000000" />
      <inertia ixx="0.000065000" ixy="0.000000000" ixz="0.000000000" iyy="0.000025000" iyz="0.000000000" izz="0.000085000"/>
    </inertial>
  </link>

  <link name="free_wheel_1">

    <visual>
      <geometry>
        <cylinder radius="0.02" length="0.1"/>
      </geometry>
    </visual>
    <collision>
      <geometry>
        <cylinder radius="0.02" length="0.1"/>
      </geometry>     
      <surface>
        <friction>
          <ode>
            <mu>0.01</mu>
            <mu2>0.01</mu2>
          </ode>
        </friction>
      </surface>


    </collision>

    <inertial>
      <origin rpy="0 0 0" xyz="0 0 0" />
      <mass value="0.500000000" />
      <inertia ixx="0.000429167" ixy="0.000000000" ixz="0.000000000" iyy="0.000429167" iyz="0.000000000" izz="0.000025000"/>
    </inertial>
          </link>

  <link name="free_wheel_2">
    <visual>
      <geometry>
        <cylinder radius="0.02" length="0.1"/>
      </geometry>
    </visual>
    <collision>
      <geometry>
        <cylinder radius="0.02" length="0.1"/>
      </geometry>

      <surface>
        <friction>
          <ode>
            <mu>0.01</mu>
            <mu2>0.01</mu2>
          </ode>
        </friction>
      </surface>



    </collision>

    <inertial>
      <origin rpy="0 0 0" xyz="0 0 0" />
      <mass value="0.500000000" />
      <inertia ixx="0.000429167" ixy="0.000000000" ixz="0.000000000" iyy="0.000429167" iyz="0.000000000" izz="0.000025000"/>
    </inertial>
        </link>












<joint name="base_joint" type="fixed">
  <parent link="base_link"/>
  <child link="body"/>
  <origin xyz="0 0 0" rpy="0 0 0"/>
</joint>


<joint name="ski_joint" type="fixed">
  <parent link="body"/>
  <child link="ski"/>
  <origin xyz="0.32 0 0.11" rpy="0 -0.5 0"/>
</joint>





<joint name="tail_plate_joint" type="continuous">
  <parent link="body"/>
  <child link="tail_plate"/>
  <axis xyz="0 0 1"/>
  <origin xyz="0 0 0.12" rpy="0 0 0"/>
</joint>



<joint name="cylinder1_joint" type="continuous">
<parent link="tail_plate"/>
<child link="cylinder1"/>
<axis xyz="0 0 1"/>
<origin xyz="0 0.07 -0.07" rpy="0.0 0 0"/>
</joint>


<joint name="cylinder2_joint" type="continuous">
<parent link="tail_plate"/>
<child link="cylinder2"/>
<axis xyz="0 0 1"/>
<origin xyz="0 -0.07 -0.07" rpy="0.0 0 0"/>
</joint>


<joint name="free_plate" type="continuous">
  <parent link="body"/>
  <child link="head_plate"/>
  <axis xyz="0 0 1"/>
  <origin xyz="0.3 0 0.12" rpy="0 0 0"/>
</joint>


<joint name="free_wheel_1_joint" type="continuous">
  <parent link="head_plate"/>
  <child link="free_wheel_1"/>
  <axis xyz="0 0 1"/>
  <origin xyz="0 0.05 -0.05" rpy="0 0 0"/>
</joint>

<joint name="free_wheel_2_joint" type="continuous">
  <parent link="head_plate"/>
  <child link="free_wheel_2"/>
  <axis xyz="0 0 1"/>
  <origin xyz="0 -0.05 -0.05" rpy="0 0 0"/>
</joint>




<transmission name="motor1_trans">
  <type>transmission_interface/SimpleTransmission</type>
  <joint name="cylinder1_joint">
    <hardwareInterface>EffortJointInterface</hardwareInterface>
  </joint>
  <actuator name="motor1_act">
    <mechanicalReduction>50</mechanicalReduction>
    <hardwareInterface>EffortJointInterface</hardwareInterface>
  </actuator>
</transmission>


<transmission name="motor2_trans">
  <type>transmission_interface/SimpleTransmission</type>
  <joint name="cylinder2_joint">
    <hardwareInterface>EffortJointInterface</hardwareInterface>
  </joint>
  <actuator name="motor1_act">
    <mechanicalReduction>50</mechanicalReduction>
    <hardwareInterface>EffortJointInterface</hardwareInterface>
  </actuator>
</transmission>


<gazebo>
  <plugin name="gazebo_ros_control" filename="libgazebo_ros_control.so">
  </plugin>
</gazebo>

 
<gazebo reference="body">
  <material>Gazebo/Green</material>


  <surface>
    <friction>
      <ode>
        <mu>0.5</mu>
        <mu2>0.5</mu2>
      </ode>
    </friction>
    <bounce>
      <restitution_coefficient>0.01</restitution_coefficient>
      <threshold>0.01</threshold>
    </bounce>
    <contact>
      <ode>
        <max_vel>0.1</max_vel>
        <soft_cfm>0.8</soft_cfm>
        <soft_erp>0.2</soft_erp>
        <kd>2500</kd>
        <kp>10</kp>
        <min_depth>0.001</min_depth>
      </ode>
    </contact>
  </surface>
  
  
</gazebo>


</robot>
